<?xml version="1.0" ?>
<!-- =================================================================================== -->
<!-- |    This document was autogenerated by xacro from robot1.urdf.xacro              | -->
<!-- |    EDITING THIS FILE BY HAND IS NOT RECOMMENDED                                 | -->
<!-- =================================================================================== -->
<robot name="robot">
  <!-- <xacro:arg name="use_lidar" default="false" /> -->
  <!-- <xacro:if value="$(arg use_lidar)">
        <xacro:include filename="lidar.xacro"/>
    </xacro:if> -->
  <!-- Materials/Colors -->
  <material name="yellow">
    <color rgba="1 1 0 1"/>
  </material>
  <material name="orange">
    <color rgba="1 0.3 0.1 1"/>
  </material>
  <material name="blue">
    <color rgba="0.2 0.2 1 1"/>
  </material>
  <material name="red">
    <color rgba="1 0 0 1"/>
  </material>
  <link name="base_footprint"/>
  <joint name="base_joint" type="fixed">
    <parent link="base_footprint"/>
    <child link="base_link"/>
    <origin rpy="0 0 0" xyz="0.12 0.0 0.0"/>
  </joint>
  <link name="base_link">
    <inertial>
      <origin rpy="0 0 0" xyz="5.30122902455545E-16 4.14241466277791E-16 0.0126948063217029"/>
      <mass value="0.629688250105366"/>
      <inertia ixx="0.0012994160656344" ixy="4.458494668736E-19" ixz="-4.06943730363067E-19" iyy="0.00233280155813295" iyz="1.19231384548009E-19" izz="0.00359571092028894"/>
    </inertial>
    <visual>
      <origin rpy="0 0 0" xyz="0 0 0"/>
      <geometry>
        <mesh filename="file:///home/cohort/cohort_ws/install/arcs_cohort_description/share/arcs_cohort_description/meshes/robot1_base_link.STL"/>
      </geometry>
      <material name="red"/>
    </visual>
    <collision>
      <origin rpy="0 0 0" xyz="0 0 0"/>
      <geometry>
        <mesh filename="file:///home/cohort/cohort_ws/install/arcs_cohort_description/share/arcs_cohort_description/meshes/robot1_base_link.STL"/>
      </geometry>
    </collision>
  </link>
  <link name="front_left_wheel_link">
    <inertial>
      <origin rpy="0 0 0" xyz="-1.888E-07 3.5593E-07 0.0069273"/>
      <mass value="0.13821"/>
      <inertia ixx="0.0003215" ixy="4.0549E-10" ixz="-2.1303E-10" iyy="0.0003215" iyz="-1.0165E-10" izz="0.00063022"/>
    </inertial>
    <visual>
      <origin rpy="0 0 0" xyz="0 0 0"/>
      <geometry>
        <mesh filename="file:///home/cohort/cohort_ws/install/arcs_cohort_description/share/arcs_cohort_description/meshes/robot1_front_left_wheel_link.STL"/>
      </geometry>
      <material name="yellow"/>
    </visual>
    <collision>
      <origin rpy="0 0 0" xyz="0 0 0"/>
      <geometry>
        <mesh filename="file:///home/cohort/cohort_ws/install/arcs_cohort_description/share/arcs_cohort_description/meshes/robot1_front_left_wheel_link.STL"/>
      </geometry>
    </collision>
  </link>
  <joint name="front_left_wheel_joint" type="continuous">
    <origin rpy="-1.57 0 0" xyz="0.108 0.089 0.01825"/>
    <parent link="base_link"/>
    <child link="front_left_wheel_link"/>
    <axis xyz="0 0 1"/>
    <dynamics damping="1000000.0" friction="0"/>
  </joint>
  <link name="front_right_wheel_link">
    <inertial>
      <origin rpy="0 0 0" xyz="-1.888E-07 3.5593E-07 0.0069273"/>
      <mass value="0.13821"/>
      <inertia ixx="0.0003215" ixy="4.0549E-10" ixz="-2.1303E-10" iyy="0.0003215" iyz="-1.0165E-10" izz="0.00063022"/>
    </inertial>
    <visual>
      <origin rpy="0 0 0" xyz="0 0 0"/>
      <geometry>
        <mesh filename="file:///home/cohort/cohort_ws/install/arcs_cohort_description/share/arcs_cohort_description/meshes/robot1_front_right_wheel_link.STL"/>
      </geometry>
      <material name="yellow"/>
    </visual>
    <collision>
      <origin rpy="0 0 0" xyz="0 0 0"/>
      <geometry>
        <mesh filename="file:///home/cohort/cohort_ws/install/arcs_cohort_description/share/arcs_cohort_description/meshes/robot1_front_right_wheel_link.STL"/>
      </geometry>
    </collision>
  </link>
  <joint name="front_right_wheel_joint" type="continuous">
    <origin rpy="1.57 0 0" xyz="0.108 -0.089 0.01825"/>
    <parent link="base_link"/>
    <child link="front_right_wheel_link"/>
    <axis xyz="0 0 -1"/>
    <dynamics damping="1000000.0" friction="0"/>
  </joint>
  <link name="zedm_camera_mount_link">
    <inertial>
      <origin rpy="0 0 0" xyz="0 0 0"/>
      <mass value="0"/>
      <inertia ixx="0" ixy="0" ixz="0" iyy="0" iyz="0" izz="0"/>
    </inertial>
    <visual>
      <origin rpy="0 0 0" xyz="0 0 0"/>
      <geometry>
        <mesh filename="file:///home/cohort/cohort_ws/install/arcs_cohort_description/share/arcs_cohort_description/meshes/robot1_camera_mount_link.STL"/>
      </geometry>
      <material name="">
        <color rgba="1 1 1 1"/>
      </material>
    </visual>
    <collision>
      <origin rpy="0 0 0" xyz="0 0 0"/>
      <geometry>
        <mesh filename="file:///home/cohort/cohort_ws/install/arcs_cohort_description/share/arcs_cohort_description/meshes/robot1_camera_mount_link.STL"/>
      </geometry>
    </collision>
  </link>
  <link name="back_left_wheel_link">
    <inertial>
      <origin rpy="0 0 0" xyz="-1.888E-07 3.5593E-07 0.0069273"/>
      <mass value="0.13821"/>
      <inertia ixx="0.0003215" ixy="4.0549E-10" ixz="-2.1303E-10" iyy="0.0003215" iyz="-1.0165E-10" izz="0.00063022"/>
    </inertial>
    <visual>
      <origin rpy="0 0 0" xyz="0 0 0"/>
      <geometry>
        <mesh filename="file:///home/cohort/cohort_ws/install/arcs_cohort_description/share/arcs_cohort_description/meshes/robot1_back_left_wheel_link.STL"/>
      </geometry>
      <material name="yellow"/>
    </visual>
    <collision>
      <origin rpy="0 0 0" xyz="0 0 0"/>
      <geometry>
        <mesh filename="file:///home/cohort/cohort_ws/install/arcs_cohort_description/share/arcs_cohort_description/meshes/robot1_back_left_wheel_link.STL"/>
      </geometry>
    </collision>
  </link>
  <joint name="back_left_wheel_joint" type="continuous">
    <origin rpy="-1.5708 0 0" xyz="-0.108 0.089 0.01825"/>
    <parent link="base_link"/>
    <child link="back_left_wheel_link"/>
    <axis xyz="0 0 1"/>
    <dynamics damping="1000000.0" friction="0"/>
  </joint>
  <joint name="camera_mount_joint" type="fixed">
    <origin rpy="0 0 0" xyz="0.1345 0.0036809 0.039145"/>
    <parent link="base_link"/>
    <child link="zedm_camera_mount_link"/>
    <axis xyz="0 0 0"/>
  </joint>
  <link name="back_right_wheel_link">
    <inertial>
      <origin rpy="0 0 0" xyz="-1.888E-07 3.5593E-07 0.0069273"/>
      <mass value="0.13821"/>
      <inertia ixx="0.0003215" ixy="4.0549E-10" ixz="-2.1303E-10" iyy="0.0003215" iyz="-1.0165E-10" izz="0.00063022"/>
    </inertial>
    <visual>
      <origin rpy="0 0 0" xyz="0 0 0"/>
      <geometry>
        <mesh filename="file:///home/cohort/cohort_ws/install/arcs_cohort_description/share/arcs_cohort_description/meshes/robot1_back_right_wheel_link.STL"/>
      </geometry>
      <material name="yellow"/>
    </visual>
    <collision>
      <origin rpy="0 0 0" xyz="0 0 0"/>
      <geometry>
        <mesh filename="file:///home/cohort/cohort_ws/install/arcs_cohort_description/share/arcs_cohort_description/meshes/robot1_back_right_wheel_link.STL"/>
      </geometry>
    </collision>
  </link>
  <joint name="back_right_wheel_joint" type="continuous">
    <origin rpy="1.5708 0 0" xyz="-0.108 -0.089 0.01825"/>
    <parent link="base_link"/>
    <child link="back_right_wheel_link"/>
    <axis xyz="0 0 -1"/>
    <dynamics damping="1000000.0" friction="0"/>
  </joint>
  <material name="zed_mat">
    <color rgba="0.8 0.8 0.8 1.0"/>
  </material>
  <material name="zedm_mat">
    <color rgba="0 0 0 1.0"/>
  </material>
  <material name="zed2_mat">
    <color rgba="0.25 0.25 0.25 1.0"/>
  </material>
  <material name="zed2i_mat">
    <color rgba="0.25 0.25 0.25 1.0"/>
  </material>
  <material name="zedx_mat">
    <color rgba="0.25 0.25 0.25 1.0"/>
  </material>
  <material name="zedxm_mat">
    <color rgba="0.25 0.25 0.25 1.0"/>
  </material>
  <material name="virtual_mat">
    <color rgba="0.25 0.25 0.25 1.0"/>
  </material>
  <material name="zedxonegs_mat">
    <color rgba="0.25 0.25 0.25 1.0"/>
  </material>
  <material name="zedxone4k_mat">
    <color rgba="0.25 0.25 0.25 1.0"/>
  </material>
  <!-- Camera mounting point (the threaded screw hole in the bottom) -->
  <link name="zedm_camera_link"/>
  <!-- Camera Center -->
  <link name="zedm_camera_center">
    <visual>
      <origin rpy="0 0 0" xyz="0.0 0 0.0"/>
      <geometry>
        <mesh filename="file:///opt/ros/jazzy/share/zed_msgs/meshes/zedm.stl"/>
      </geometry>
      <material name="zedm_mat"/>
    </visual>
    <collision>
      <origin rpy="0 0 0" xyz="0.0 0 0.0"/>
      <geometry>
        <mesh filename="file:///opt/ros/jazzy/share/zed_msgs/meshes/zedm.stl"/>
      </geometry>
    </collision>
  </link>
  <joint name="zedm_camera_center_joint" type="fixed">
    <parent link="zedm_camera_link"/>
    <child link="zedm_camera_center"/>
    <origin rpy="0 0.0 0" xyz="0 0 0.01325"/>
  </joint>
  <!-- Left Camera -->
  <link name="zedm_left_camera_frame">
  </link>
  <joint name="zedm_left_camera_joint" type="fixed">
    <parent link="zedm_camera_center"/>
    <child link="zedm_left_camera_frame"/>
    <origin rpy="0 0 0" xyz="0.0 0.0315 0"/>
  </joint>
  <link name="zedm_left_camera_optical_frame"/>
  <joint name="zedm_left_camera_optical_joint" type="fixed">
    <origin rpy="-1.5707963267948966 0.0 -1.5707963267948966" xyz="0 0 0"/>
    <parent link="zedm_left_camera_frame"/>
    <child link="zedm_left_camera_optical_frame"/>
  </joint>
  <!-- Right Camera -->
  <link name="zedm_right_camera_frame">
  </link>
  <joint name="zedm_right_camera_joint" type="fixed">
    <parent link="zedm_camera_center"/>
    <child link="zedm_right_camera_frame"/>
    <origin rpy="0 0 0" xyz="0.0 -0.0315 0"/>
  </joint>
  <link name="zedm_right_camera_optical_frame"/>
  <joint name="zedm_right_camera_optical_joint" type="fixed">
    <origin rpy="-1.5707963267948966 0.0 -1.5707963267948966" xyz="0 0 0"/>
    <parent link="zedm_right_camera_frame"/>
    <child link="zedm_right_camera_optical_frame"/>
  </joint>
  <!--Camera-->
  <joint name="zedm_camera_mount_to_camera" type="fixed">
    <parent link="zedm_camera_mount_link"/>
    <child link="zedm_camera_link"/>
    <origin rpy="0 0 0" xyz="0.015 -0.0068 0"/>
  </joint>
</robot>
